<?xml version="1.0" encoding="utf-8"?>
<!-- =================================================================================== -->
<!-- |    This document was autogenerated by xacro from macros.xacro                   | -->
<!-- |    EDITING THIS FILE BY HAND IS NOT RECOMMENDED                                 | -->
<!-- =================================================================================== -->
<robot name="virtual_robot">
  <!-- ###### INERTIA, VISUAL, & COLLISION MACROS ####################################-->
  <!-- inertial parameter macros -->
  <!-- visual geometry macros -->
  <!-- collision macros -->
  <!-- transmission macros -->
  <!-- ###### LINK & JOINT DEFINTIONS ####################################-->
  <!-- Add chassis and it's inertia link -->
  <link name="car_1_base_link"/>
  <link name="car_1_chassis">
    <visual>
      <origin rpy="-1.5708 0 3.1416" xyz="0.165 0.3305 -0.01"/>
      <geometry>
        <mesh filename="package://f1tenth-sim/urdf/meshes/chassis.STL" scale="0.00095 0.000925 0.000925"/>
      </geometry>
      <material name="red"/>
    </visual>
    <!-- <collision>
      <xacro:chassis_collision_geometry />
    </collision>
    <surface>
        <friction>
            <ode>
                <mu>${WHEELSURFACEFRICTION}</mu>
                <mu2>${WHEELSURFACEFRICTION}</mu2>
                <slip1>${WHEELSURFACESLIP}</slip1>
                <slip2>${WHEELSURFACESLIP}</slip2>
            </ode>
        </friction>
    </surface> -->
  </link>
  <joint name="car_1_base_link_joint" type="fixed">
    <origin rpy="0 0 0" xyz="0 0 0.05"/>
    <parent link="car_1_base_link"/>
    <child link="car_1_chassis"/>
  </joint>
  <link name="car_1_chassis_inertia">
    <inertial>
      <origin rpy="0 0 0" xyz="0.1477 0 0"/>
      <mass value="20.0"/>
      <inertia ixx="1.36333333333" ixy="0" ixz="0" iyy="0.468166666667" iyz="0" izz="1.57016666667"/>
      <!-- <inertia ixx="0.010609" ixy="0"          ixz="0"
                            iyy="0.050409"   iyz="0"
                                             izz="0.05865" /> -->
    </inertial>
  </link>
  <joint name="car_1_chassis_inertia_joint" type="fixed">
    <origin rpy="0 0 0" xyz="0 0 0"/>
    <parent link="car_1_chassis"/>
    <child link="car_1_chassis_inertia"/>
  </joint>
  <!-- Add the left front wheel with its joints and transmissions -->
  <link name="car_1_left_front_wheel">
    <inertial>
      <origin rpy="0 0 0" xyz="0 0 0.0225"/>
      <mass value="0.453592"/>
      <inertia ixx="0.000826397374833" ixy="0" ixz="0" iyy="0.000826397374833" iyz="0" izz="0.00438589880657"/>
      <!-- <inertia ixx="0.00026046" ixy="0"          ixz="0"
                                  iyy="0.00026046" iyz="0"
                                                  izz="0.00041226" /> -->
    </inertial>
    <visual>
      <origin rpy="0 0 0" xyz="0 0 0.0225"/>
      <geometry>
        <mesh filename="package://f1tenth-sim/urdf/meshes/wheel.dae" scale="0.0012 0.0012 0.0012"/>
      </geometry>
      <material name="black"/>
    </visual>
    <collision>
      <origin rpy="0 0 0" xyz="0 0 0.0225"/>
      <geometry>
        <cylinder length="0.06" radius="0.055"/>
      </geometry>
    </collision>
    <surface>
      <friction>
        <ode>
          <mu>0.9</mu>
          <mu2>0.9</mu2>
          <slip1>0.1</slip1>
          <slip2>0.1</slip2>
        </ode>
      </friction>
    </surface>
  </link>
  <joint name="car_1_left_front_wheel_joint" type="continuous">
    <origin rpy="-1.5708 0 0" xyz="0 0 0"/>
    <parent link="car_1_left_steering_hinge"/>
    <child link="car_1_left_front_wheel"/>
    <axis xyz="0 0 1"/>
    <joint_properties damping="0.5" friction="0.5"/>
    <limit effort="20" velocity="300"/>
  </joint>
  <transmission name="car_1_left_front_wheel_transmission" type="SimpleTransmission">
    <type>transmission_interface/SimpleTransmission</type>
    <joint name="car_1_left_front_wheel_joint">
      <hardwareInterface>hardware_interface/EffortJointInterface</hardwareInterface>
    </joint>
    <actuator name="car_1_left_front_wheel_motor">
      <hardwareInterface>hardware_interface/EffortJointInterface</hardwareInterface>
      <mechanicalReduction>1</mechanicalReduction>
    </actuator>
  </transmission>
  <!-- Add the left rear wheel with its joints and transmissions -->
  <link name="car_1_left_rear_wheel">
    <inertial>
      <origin rpy="0 0 0" xyz="0 0 0.0225"/>
      <mass value="0.453592"/>
      <inertia ixx="0.000826397374833" ixy="0" ixz="0" iyy="0.000826397374833" iyz="0" izz="0.00438589880657"/>
      <!-- <inertia ixx="0.00026046" ixy="0"          ixz="0"
                                  iyy="0.00026046" iyz="0"
                                                  izz="0.00041226" /> -->
    </inertial>
    <visual>
      <origin rpy="0 0 0" xyz="0 0 0.0225"/>
      <geometry>
        <mesh filename="package://f1tenth-sim/urdf/meshes/wheel.dae" scale="0.0012 0.0012 0.0012"/>
      </geometry>
      <material name="black"/>
    </visual>
    <collision>
      robot
      
      <origin rpy="0 0 0" xyz="0 0 0.0225"/>
      <geometry>
        <cylinder length="0.06" radius="0.055"/>
      </geometry>
    </collision>
    <surface>
      <friction>
        <ode>
          <mu>0.9</mu>
          <mu2>0.9</mu2>
          <slip1>0.1</slip1>
          <slip2>0.1</slip2>
        </ode>
      </friction>
    </surface>
  </link>
  <joint name="car_1_left_rear_wheel_joint" type="continuous">
    <origin rpy="-1.5708 0 0" xyz="0 0.1 0"/>
    <parent link="car_1_chassis"/>
    <child link="car_1_left_rear_wheel"/>
    <axis xyz="0 0 1"/>
    <limit effort="20" velocity="300"/>
  </joint>
  <transmission name="car_1_left_rear_wheel_transmission" type="SimpleTransmission">
    <type>transmission_interface/SimpleTransmission</type>
    <joint name="car_1_left_rear_wheel_joint">
      <hardwareInterface>hardware_interface/EffortJointInterface</hardwareInterface>
    </joint>
    <actuator name="car_1_left_rear_wheel_motor">
      <hardwareInterface>hardware_interface/EffortJointInterface</hardwareInterface>
      <mechanicalReduction>1</mechanicalReduction>
    </actuator>
  </transmission>
  <!-- Add the right front wheel with its joints and transmissions -->
  <link name="car_1_right_front_wheel">
    <inertial>
      <origin rpy="0 0 0" xyz="0 0 0.0225"/>
      <mass value="0.453592"/>
      <inertia ixx="0.000826397374833" ixy="0" ixz="0" iyy="0.000826397374833" iyz="0" izz="0.00438589880657"/>
      <!-- <mass value="0.453592" />
    <inertia ixx="0.00026046" ixy="0"          ixz="0"
                              iyy="0.00026046" iyz="0"
                                               izz="0.00041226" /> -->
    </inertial>
    <visual>
      <origin rpy="0 0 0" xyz="0 0 0.0225"/>
      <geometry>
        <mesh filename="package://f1tenth-sim/urdf/meshes/wheel.dae" scale="0.0012 0.0012 0.0012"/>
      </geometry>
      <material name="black"/>
    </visual>
    <collision>
      <origin rpy="0 0 0" xyz="0 0 0.0225"/>
      <geometry>
        <cylinder length="0.06" radius="0.055"/>
      </geometry>
    </collision>
    <surface>
      <friction>
        <ode>
          <mu>0.9</mu>
          <mu2>0.9</mu2>
          <slip1>0.1</slip1>
          <slip2>0.1</slip2>
        </ode>
      </friction>
    </surface>
  </link>
  <joint name="car_1_right_front_wheel_joint" type="continuous">
    <origin rpy="1.5708 0 0" xyz="0 0 0"/>
    <parent link="car_1_right_steering_hinge"/>
    <child link="car_1_right_front_wheel"/>
    <axis xyz="0 0 -1"/>
    <limit effort="20" velocity="300"/>
  </joint>
  <transmission name="car_1_right_front_wheel_transmission" type="SimpleTransmission">
    <type>transmission_interface/SimpleTransmission</type>
    <joint name="car_1_right_front_wheel_joint">
      <hardwareInterface>hardware_interface/EffortJointInterface</hardwareInterface>
    </joint>
    <actuator name="car_1_right_front_wheel_motor">
      <hardwareInterface>hardware_interface/EffortJointInterface</hardwareInterface>
      <mechanicalReduction>1</mechanicalReduction>
    </actuator>
  </transmission>
  <!-- Add the right rear wheel with its joints and transmissions -->
  <link name="car_1_right_rear_wheel">
    <inertial>
      <origin rpy="0 0 0" xyz="0 0 0.0225"/>
      <mass value="0.453592"/>
      <inertia ixx="0.000826397374833" ixy="0" ixz="0" iyy="0.000826397374833" iyz="0" izz="0.00438589880657"/>
      <!-- <mass value="0.453592" />
    <inertia ixx="0.00026046" ixy="0"          ixz="0"
                              iyy="0.00026046" iyz="0"
                                               izz="0.00041226" /> -->
    </inertial>
    <visual>
      <origin rpy="0 0 0" xyz="0 0 0.0225"/>
      <geometry>
        <mesh filename="package://f1tenth-sim/urdf/meshes/wheel.dae" scale="0.0012 0.0012 0.0012"/>
      </geometry>
      <material name="red"/>
    </visual>
    <collision>
      <origin rpy="0 0 0" xyz="0 0 0.0225"/>
      <geometry>
        <cylinder length="0.06" radius="0.055"/>
      </geometry>
    </collision>
    <surface>
      <friction>
        <ode>
          <mu>0.9</mu>
          <mu2>0.9</mu2>
          <slip1>0.1</slip1>
          <slip2>0.1</slip2>
        </ode>
      </friction>
    </surface>
  </link>
  <joint name="car_1_right_rear_wheel_joint" type="continuous">
    <origin rpy="1.5708 0 0" xyz="0 -0.1 0"/>
    <parent link="car_1_chassis"/>
    <child link="car_1_right_rear_wheel"/>
    <axis xyz="0 0 -1"/>
    <limit effort="20" velocity="300"/>
  </joint>
  <transmission name="car_1_right_rear_wheel_transmission" type="SimpleTransmission">
    <type>transmission_interface/SimpleTransmission</type>
    <joint name="car_1_right_rear_wheel_joint">
      <hardwareInterface>hardware_interface/EffortJointInterface</hardwareInterface>
    </joint>
    <actuator name="car_1_right_rear_wheel_motor">
      <hardwareInterface>hardware_interface/EffortJointInterface</hardwareInterface>
      <mechanicalReduction>1</mechanicalReduction>
    </actuator>
  </transmission>
  <!-- Add the left steering hinge with its joints and transmissions -->
  <link name="car_1_left_steering_hinge">
    <inertial>
      <origin rpy="0 0 0" xyz="0 0 0"/>
      <mass value="0.100"/>
      <inertia ixx="4E-06" ixy="0" ixz="0" iyy="4E-06" iyz="0" izz="4E-06"/>
    </inertial>
    <visual>
      <origin rpy="0 0 0" xyz="0 0 0"/>
      <geometry>
        <mesh filename="package://f1tenth-sim/urdf/meshes/hinge.stl"/>
      </geometry>
      <material name="grey"/>
    </visual>
  </link>
  <joint name="car_1_left_steering_hinge_joint" type="revolute">
    <origin rpy="0 0 0" xyz="0.325 0.1 0"/>
    <parent link="car_1_chassis"/>
    <child link="car_1_left_steering_hinge"/>
    <axis xyz="0 0 1"/>
    <limit effort="10" lower="-0.523599" upper="0.523599" velocity="100"/>
  </joint>
  <transmission name="car_1_left_steering_hinge_transmission" type="SimpleTransmission">
    <type>transmission_interface/SimpleTransmission</type>
    <joint name="car_1_left_steering_hinge_joint">
      <hardwareInterface>hardware_interface/EffortJointInterface</hardwareInterface>
    </joint>
    <actuator name="car_1_left_steering_hinge_motor">
      <hardwareInterface>hardware_interface/EffortJointInterface</hardwareInterface>
      <mechanicalReduction>1</mechanicalReduction>
    </actuator>
  </transmission>
  <!-- Add the right steering hinge with its joints and transmissions -->
  <link name="car_1_right_steering_hinge">
    <inertial>
      <origin rpy="0 0 0" xyz="0 0 0"/>
      <mass value="0.100"/>
      <inertia ixx="4E-06" ixy="0" ixz="0" iyy="4E-06" iyz="0" izz="4E-06"/>
    </inertial>
    <visual>
      <origin rpy="0 0 0" xyz="0 0 0"/>
      <geometry>
        <mesh filename="package://f1tenth-sim/urdf/meshes/hinge.stl"/>
      </geometry>
      <material name="grey"/>
    </visual>
  </link>
  <joint name="car_1_right_steering_hinge_joint" type="revolute">
    <origin rpy="0 0 0" xyz="0.325 -0.1 0"/>
    <parent link="car_1_chassis"/>
    <child link="car_1_right_steering_hinge"/>
    <axis xyz="0 0 1"/>
    <limit effort="10" lower="-0.523599" upper="0.523599" velocity="100"/>
  </joint>
  <transmission name="car_1_right_steering_hinge_transmission" type="SimpleTransmission">
    <type>transmission_interface/SimpleTransmission</type>
    <joint name="car_1_right_steering_hinge_joint">
      <hardwareInterface>hardware_interface/EffortJointInterface</hardwareInterface>
    </joint>
    <actuator name="car_1_right_steering_hinge_motor">
      <hardwareInterface>hardware_interface/EffortJointInterface</hardwareInterface>
      <mechanicalReduction>1</mechanicalReduction>
    </actuator>
  </transmission>
  <!-- Add Hokuyo laser scanner -->
  <link name="car_1_laser">
    <inertial>
      <origin rpy="0 0 0" xyz="0 0 0"/>
      <mass value="0.130"/>
      <inertia ixx="4E-06" ixy="0" ixz="0" iyy="4E-06" iyz="0" izz="4E-06"/>
    </inertial>
    <collision>
      <origin rpy="0 0 0" xyz="0 0 0"/>
      <geometry>
        <box size="0.060 0.060 0.080"/>
      </geometry>
    </collision>
    <visual>
      <origin rpy="0 0 0" xyz="0 0 0"/>
      <geometry>
        <mesh filename="package://f1tenth-sim/urdf/meshes/hokuyo.stl"/>
        <material name="grey"/>
      </geometry>
    </visual>
  </link>
  <joint name="car_1_hokuyo_joint" type="fixed">
    <origin rpy="0 0 0" xyz="0.35 0.0 0.075"/>
    <parent link="car_1_chassis"/>
    <child link="car_1_laser"/>
    <axis xyz="0 0 1"/>
  </joint>
  <!-- camera class (spawn parameters) -->
  <!-- <link name="$(arg robot_name)_link">
    <inertial>
      <mass value="1e-5" />
      <origin xyz="0 0 0.25" rpy="0 0 0"/>
      <inertia ixx="1e-6" ixy="0" ixz="0" iyy="1e-6" iyz="0" izz="1e-6" />
    </inertial>
    <collision>
      <origin xyz="0 0 0.25" rpy="0 0 0"/>
      <geometry>
        <box size="0.033 0.175 0.030"/>
      </geometry>
    </collision>
    <visual>
      <origin xyz="0 0 0.025" rpy="0 0 0"/>
      <geometry>
        <box size="0.033 0.175 0.030"/>
      </geometry>
      <material name="red"/>
    </visual>
  </link>

  <joint name="$(arg robot_name)_joint" type="fixed">
    <origin xyz="0.390 0 0.025" rpy="0 0 0"/>
    <parent link="$(arg robot_name)_chassis"/>
    <child link="$(arg robot_name)_link"/>
    <axis xyz="0 0 1" />
  </joint> -->
  <!-- camera lenses -->
  <!-- <link name="$(arg robot_name)_camera_link">
    <inertial>
      <mass value="1e-5" />
      <origin xyz="-2.5 1.5 1.75" rpy="0 .57 -0.57"/>
      <inertia ixx="1e-6" ixy="0" ixz="0" iyy="1e-6" iyz="0" izz="1e-6" />
    </inertial>
  </link>
  <link name="$(arg robot_name)_right_link">
    <inertial>
      <mass value="1e-5" />
      <origin xyz="-2.5 1.5 1.75" rpy="0 .57 -0.57"/>
      <inertia ixx="1e-6" ixy="0" ixz="0" iyy="1e-6" iyz="0" izz="1e-6" />
    </inertial>
  </link>

  <joint name="$(arg robot_name)_left_joint" type="fixed">
    <origin xyz="-2.5 1.5 1.75" rpy="0 .57 -0.57"/>
    <parent link="$(arg robot_name)_link"/>
    <child link="$(arg robot_name)_camera_link"/>
    <axis xyz="0 0 1" />
  </joint>
  <joint name="$(arg robot_name)_right_joint" type="fixed">
    <origin xyz="0 -0.06 0.025" rpy="0 0 0"/>
    <parent link="$(arg robot_name)_link"/>
    <child link="$(arg robot_name)_right_link"/>
    <axis xyz="0 0 1" />
  </joint> -->
  <!-- #### GAZEBO SIMULATION SETTINGS #### -->
  <!-- Gazebo Material References -->
  <gazebo reference="car_1_chassis">
    <kp value="10000000.0"/>
    <kd value="1.0"/>
    <material>Gazebo/Blue</material>
  </gazebo>
  <gazebo reference="car_1_left_rear_wheel">
    <kp value="10000000.0"/>
    <kd value="1.0"/>
    <material>Gazebo/DarkGrey</material>
  </gazebo>
  <gazebo reference="car_1_right_rear_wheel">
    <kp value="10000000.0"/>
    <kd value="1.0"/>
    <material>Gazebo/DarkGrey</material>
  </gazebo>
  <gazebo reference="car_1_left_front_wheel">
    <kp value="10000000.0"/>
    <kd value="1.0"/>
    <material>Gazebo/DarkGrey</material>
  </gazebo>
  <gazebo reference="car_1_right_front_wheel">
    <kp value="10000000.0"/>
    <kd value="1.0"/>
    <material>Gazebo/DarkGrey</material>
  </gazebo>
  <!-- Gazebo plugins -->
  <gazebo>
    <plugin filename="libgazebo_ros_control.so" name="gazebo_ros_control">
      <robotNamespace>/car_1</robotNamespace>
      <robotSimType>gazebo_ros_control/DefaultRobotHWSim</robotSimType>
    </plugin>
  </gazebo>
  <!-- Odometry (cheap hack) -->
  <gazebo>
    <plugin filename="libgazebo_ros_p3d.so" name="p3d_base_controller">
      <alwaysOn>true</alwaysOn>
      <updateRate>50.0</updateRate>
      <bodyName>car_1_base_link</bodyName>
      <topicName>/car_1/ground_truth</topicName>
      <gaussianNoise>0.01</gaussianNoise>
      <frameName>world</frameName>
      <xyzOffsets>0 0 0</xyzOffsets>
      <rpyOffsets>0 0 0</rpyOffsets>
    </plugin>
  </gazebo>
  <gazebo reference="car_1_laser">
    <material>Gazebo/Grey</material>
    <sensor name="car_1_hokuyo_sensor" type="ray">
      <pose>0 0 0.0124 0 0 0</pose>
      <visualize>true</visualize>
      <update_rate>40</update_rate>
      <ray>
        <scan>
          <horizontal>
            <samples>1081</samples>
            <resolution>1</resolution>
            <min_angle>-2.3561944902</min_angle>
            <max_angle>2.3561944902</max_angle>
          </horizontal>
        </scan>
        <range>
          <min>0.1</min>
          <max>30.0</max>
          <resolution>0.01</resolution>
        </range>
        <noise>
          <mean>0.0</mean>
          <stddev>0.01</stddev>
        </noise>
      </ray>
      <plugin filename="libgazebo_ros_laser.so" name="gazebo_ros_hokuyo_controller">
        <topicName>/car_1/scan</topicName>
        <frameName>car_1_laser</frameName>
      </plugin>
    </sensor>
  </gazebo>
  <gazebo reference="car_1_camera_link">
    <sensor name="car_1_left_sensor" type="camera">
      <update_rate>30.0</update_rate>
      <!-- math.atan(320 / 687.8065795898438) * 2 -->
      <camera name="front_camera">
        <!-- horizontal_fov>0.8709216071359963</horizontal_fov -->
        <horizontal_fov>1.74</horizontal_fov>
        <image>
          <width>1920</width>
          <height>1080</height>
          <format>B8G8R8</format>
        </image>
        <clip>
          <near>0.02</near>
          <far>300</far>
        </clip>
        <noise>
          <type>gaussian</type>
          <mean>0.0</mean>
          <stddev>0.007</stddev>
        </noise>
      </camera>
      <plugin filename="libgazebo_ros_camera.so" name="camera_controller">
        <alwaysOn>true</alwaysOn>
        <updateRate>30.0</updateRate>
        <cameraName>/car_1/camera</cameraName>
        <imageTopicName>image</imageTopicName>
        <cameraInfoTopicName>rgb/camera_info</cameraInfoTopicName>
        <frameName>car_1_camera_link</frameName>
        <hackBaseline>0</hackBaseline>
        <!-- set this to 0.12 for the second camera -->
        <distortionK1>0.0</distortionK1>
        <distortionK2>0.0</distortionK2>
        <distortionK3>0.0</distortionK3>
        <distortionT1>0.0</distortionT1>
        <distortionT2>0.0</distortionT2>
      </plugin>
    </sensor>
  </gazebo>
  <material name="black">
    <color rgba="0.0 0.0 0.0 1.0"/>
  </material>
  <material name="blue">
    <color rgba="0.0 0.0 0.8 1.0"/>
  </material>
  <material name="green">
    <color rgba="0.0 0.8 0.0 1.0"/>
  </material>
  <material name="grey">
    <color rgba="0.2 0.2 0.2 1.0"/>
  </material>
  <material name="orange">
    <color rgba="1.0 0.423529411765 0.0392156862745 1.0"/>
  </material>
  <material name="brown">
    <color rgba="0.870588235294 0.811764705882 0.764705882353 1.0"/>
  </material>
  <material name="red">
    <color rgba="0.8 0.0 0.0 1.0"/>
  </material>
  <material name="white">
    <color rgba="1.0 1.0 1.0 1.0"/>
  </material>
</robot>

